<robot name="example_robot">

    <link name="base_link" />

    <joint name="example_joint" type="revolute">
        <parent link="base_link" />
        <child link="example_link" />
        <limit lower="0" upper="3.14" effort="10.0" velocity="1.0" />
    </joint>
    
    <transmission name="example_joint_transmission">
        <type>transmission_interface/SimpleTransmission</type>
        <joint name="example_joint">
            <hardwareInterface>hardware_interface/PositionJointInterface</hardwareInterface>
            <hardwareInterface>hardware_interface/VelocityJointInterface</hardwareInterface>
            <hardwareInterface>hardware_interface/EffortJointInterface</hardwareInterface>
        </joint>
        <actuator name="example_actuator">
            <mechanicalReduction>50</mechanicalReduction>
        </actuator>
    </transmission>

    <link name="example_link" />

</robot>